Workbook

Sheet 硬件清单
A1: 顺序号 | B1: 原表序号 | C1: 清查表序号 | D1: 产品大类 | E1: 产品 | F1: 维保内容 | G1: S/N | H1: 固资编号 | I1: 维保期限（月） | K1: 备注 | L1: 是否原厂 | M1: 安装地点
A2: =IF(C2="","",SUBTOTAL(103,$C$2:C2)) -> 1 | B2: 806 | C2: 5381 | D2: 机房设备 | E2: UPS系统（含电池组） | F2: 施耐德MGE Galaxy 7000 500KVA1及伊顿9395 500KVA | G2: 施耐德：UJ-2W7T04001、伊顿:4L385BAB03 | H2: 140701-2017-000002 | I2: 12 | J2: =VLOOKUP(G2,[1]硬件清单!$F:$F,1,0) -> 施耐德：UJ-2W7T04001、伊顿:4L385BAB03 | K2: =VLOOKUP(G2,[1]硬件清单!$F:$F,1,0) -> 施耐德：UJ-2W7T04001、伊顿:4L385BAB03 | L2: 原厂 | M2: TK-F01-配电间东侧
A3: =IF(C3="","",SUBTOTAL(103,$C$2:C3)) -> 2 | B3: 5298 | C3: 713 | D3: 网络设备 | E3: 交换机 | F3: 广州毅航ISX6000 | G3: SNC-4000V3.0-201534-0025 SNC-4000V3.0-201534-0001 SNC-4000V3.0-291215-00211 SNC-4000V3.0-291215-00212 201804260092 201804260032 | H3: 140502-2019-000143 | I3: 12 | J3: =VLOOKUP(G3,[1]硬件清单!$F:$F,1,0) -> SNC-4000V3.0-201534-0025 SNC-4000V3.0-201534-0001 SNC-4000V3.0-291215-00211 SNC-4000V3.0-291215-00212 201804260092 201804260032 | K3: =VLOOKUP(G3,[1]硬件清单!$F:$F,1,0) -> SNC-4000V3.0-201534-0025 SNC-4000V3.0-201534-0001 SNC-4000V3.0-291215-00211 SNC-4000V3.0-291215-00212 201804260092 201804260032 | M3: XD-B02-KF-E12(35-37U) XD-B02-KF-E12(33-34U)电源
A4: =IF(C4="","",SUBTOTAL(103,$C$2:C4)) -> 3 | B4: 5299 | C4: 714 | D4: 网络设备 | E4: 交换机 | F4: 广州毅航ISX6000 | G4: SNC-4000V3.0-201534-0027 SNC-4000V3.0-201534-0023 201811220063 201804260095 | H4: 140502-2019-000144 | I4: 12 | J4: =VLOOKUP(G4,[1]硬件清单!$F:$F,1,0) -> SNC-4000V3.0-201534-0027 SNC-4000V3.0-201534-0023 201811220063 201804260095 | K4: =VLOOKUP(G4,[1]硬件清单!$F:$F,1,0) -> SNC-4000V3.0-201534-0027 SNC-4000V3.0-201534-0023 201811220063 201804260095 | M4: XD-B02-KF-E13(33-34U) XD-B02-KF-E13(37-38U)电源
A5: =IF(C5="","",SUBTOTAL(103,$C$2:C5)) -> 4 | B5: 5300 | C5: 715 | D5: 网络设备 | E5: 交换机 | F5: 广州毅航ISX6000 | G5: SNC-4000V3.0-201534-0026 SNC-4000V3.0-201534-0024 201811220094 201811220027 | H5: 140502-2019-000145 | I5: 12 | J5: =VLOOKUP(G5,[1]硬件清单!$F:$F,1,0) -> SNC-4000V3.0-201534-0026 SNC-4000V3.0-201534-0024 201811220094 201811220027 | K5: =VLOOKUP(G5,[1]硬件清单!$F:$F,1,0) -> SNC-4000V3.0-201534-0026 SNC-4000V3.0-201534-0024 201811220094 201811220027 | M5: XD-B02-KF-E13(30-31U) XD-B02-KF-E13(35-36U)电源
A6: =IF(C6="","",SUBTOTAL(103,$C$2:C6)) -> 5 | B6: 5301 | C6: 716 | D6: 网络设备 | E6: 交换机 | F6: 广州毅航ISX6000 | G6: SNC-4000V3.0-201534-0021 SNC-4000V3.0-201534-0022 201804260025 201804260021 | H6: 140502-2019-000146 | I6: 12 | J6: =VLOOKUP(G6,[1]硬件清单!$F:$F,1,0) -> SNC-4000V3.0-201534-0021 SNC-4000V3.0-201534-0022 201804260025 201804260021 | K6: =VLOOKUP(G6,[1]硬件清单!$F:$F,1,0) -> SNC-4000V3.0-201534-0021 SNC-4000V3.0-201534-0022 201804260025 201804260021 | M6: XD-B02-KF-E14(30-31U) XD-B02-KF-E14(32-33U)电源
A7: =IF(C7="","",SUBTOTAL(103,$C$2:C7)) -> 6 | B7: 5302 | C7: 717 | D7: 网络设备 | E7: 其他网络设备 | F7: 华为 Optix-OSN-1500 | G7: 2102300653P0KB000260 | H7: 140506-2019-000027 | I7: 12 | J7: =VLOOKUP(G7,[1]硬件清单!$F:$F,1,0) -> 2102300653P0KB000260 | K7: =VLOOKUP(G7,[1]硬件清单!$F:$F,1,0) -> 2102300653P0KB000260 | M7: XD-B02-KF-E05(31-35U)
A8: =IF(C8="","",SUBTOTAL(103,$C$2:C8)) -> 7 | B8: 5303 | C8: 718 | D8: 网络设备 | E8: 其他网络设备 | F8: 华为 Optix-OSN-1500 | G8: 2102300653P0KB000259 | H8: 140506-2019-000028 | I8: 12 | J8: =VLOOKUP(G8,[1]硬件清单!$F:$F,1,0) -> 2102300653P0KB000259 | K8: =VLOOKUP(G8,[1]硬件清单!$F:$F,1,0) -> 2102300653P0KB000259 | M8: XD-B02-KF-E06(31-35U)
A9: =IF(C9="","",SUBTOTAL(103,$C$2:C9)) -> 8 | B9: 5304 | C9: 719 | D9: 网络设备 | E9: 其他网络设备 | F9: 华为 Optix-OSN-1500 | G9: 2102300653P0KB000261 | H9: 140506-2019-000029 | I9: 12 | J9: =VLOOKUP(G9,[1]硬件清单!$F:$F,1,0) -> 2102300653P0KB000261 | K9: =VLOOKUP(G9,[1]硬件清单!$F:$F,1,0) -> 2102300653P0KB000261 | M9: XD-B02-KF-E07(31-35U)
A10: =IF(C10="","",SUBTOTAL(103,$C$2:C10)) -> 9 | B10: 11512 | C10: 169 | D10: 计算机 | E10: 其他计算机 | F10: 朗阁MailData邮件网关系统 | G10: MDLZ-K1115-2U16S-2620V4-OBCR | H10: 140107-2020-000001 | I10: 12 | J10: =VLOOKUP(G10,[1]硬件清单!$F:$F,1,0) -> MDLZ-K1115-2U16S-2620V4-OBCR | K10: =VLOOKUP(G10,[1]硬件清单!$F:$F,1,0) -> MDLZ-K1115-2U16S-2620V4-OBCR | M10: XD-B03-YD-C10(37-38U)
A11: =IF(C11="","",SUBTOTAL(103,$C$2:C11)) -> 10 | B11: 11513 | C11: 170 | D11: 计算机 | E11: 其他计算机 | F11: 朗阁MailData邮件网关系统 | G11: MDLZ-K1115-2U16S-2620V4-OBCQ | H11: 140107-2020-000002 | I11: 12 | J11: =VLOOKUP(G11,[1]硬件清单!$F:$F,1,0) -> MDLZ-K1115-2U16S-2620V4-OBCQ | K11: =VLOOKUP(G11,[1]硬件清单!$F:$F,1,0) -> MDLZ-K1115-2U16S-2620V4-OBCQ | M11: XD-B03-YD-C10(35-36U)
A12: =IF(C12="","",SUBTOTAL(103,$C$2:C12)) -> 11 | B12: 11514 | C12: 184 | D12: 计算机 | E12: 其他计算机 | F12: 朗阁MailData邮件网关系统 | G12: MDLZ-K1115-2U16S-2620V4-OBEB | H12: 140107-2020-000003 | I12: 12 | J12: =VLOOKUP(G12,[1]硬件清单!$F:$F,1,0) -> MDLZ-K1115-2U16S-2620V4-OBEB | K12: =VLOOKUP(G12,[1]硬件清单!$F:$F,1,0) -> MDLZ-K1115-2U16S-2620V4-OBEB | M12: XD-B03-YD-C10(41-42U)
A13: =IF(C13="","",SUBTOTAL(103,$C$2:C13)) -> 12 | B13: 11515 | C13: 185 | D13: 计算机 | E13: 其他计算机 | F13: 朗阁MailData邮件网关系统 | G13: MDLZ-K1115-2U16S-2620V4-OBEA | H13: 140107-2020-000004 | I13: 12 | J13: =VLOOKUP(G13,[1]硬件清单!$F:$F,1,0) -> MDLZ-K1115-2U16S-2620V4-OBEA | K13: =VLOOKUP(G13,[1]硬件清单!$F:$F,1,0) -> MDLZ-K1115-2U16S-2620V4-OBEA | M13: XD-B03-YD-C10(39-40U)
A14: =IF(C14="","",SUBTOTAL(103,$C$2:C14)) -> 13 | B14: 1 | C14: 11183 | D14: 网络设备 | E14: 链路负载均衡器 | F14: F5 VIPROPN 2400 | G14: chs408148s | H14: 140503-2014-000220 | I14: 12 | J14: =VLOOKUP(G14,[1]硬件清单!$F:$F,1,0) -> chs408148s | K14: =VLOOKUP(G14,[1]硬件清单!$F:$F,1,0) -> chs408148s | L14: 原厂 | M14: TK-F01-101-G2(27-30U)
A15: =IF(C15="","",SUBTOTAL(103,$C$2:C15)) -> 14 | B15: 2 | C15: 11201 | D15: 安全保密 | E15: 防火墙 | F15: 华为 USG6660 | G15: 210235G7G510EA000007 | H15: 140601-2014-000012 | I15: 12 | J15: =VLOOKUP(G15,[1]硬件清单!$F:$F,1,0) -> 210235G7G510EA000007 | K15: =VLOOKUP(G15,[1]硬件清单!$F:$F,1,0) -> 210235G7G510EA000007 | M15: TK-F01-101-G2(35-37U)
A16: =IF(C16="","",SUBTOTAL(103,$C$2:C16)) -> 15 | B16: 3 | C16: 11100 | D16: 网络设备 | E16: 交换机 | F16: 华三 S12510-X | G16: 210235AOXXX149000045 | H16: 140502-2014-001091 | I16: 12 | J16: =VLOOKUP(G16,[1]硬件清单!$F:$F,1,0) -> 210235AOXXX149000045 | K16: =VLOOKUP(G16,[1]硬件清单!$F:$F,1,0) -> 210235AOXXX149000045 | L16: 原厂 | M16: TK-F01-101-G3(3-23U)
A17: =IF(C17="","",SUBTOTAL(103,$C$2:C17)) -> 16 | B17: 4 | C17: 11184 | D17: 网络设备 | E17: 链路负载均衡器 | F17: F5 VIPROPN 2400 | G17: chs408167s | H17: 140503-2014-000221 | I17: 12 | J17: =VLOOKUP(G17,[1]硬件清单!$F:$F,1,0) -> chs408167s | K17: =VLOOKUP(G17,[1]硬件清单!$F:$F,1,0) -> chs408167s | L17: 原厂 | M17: TK-F01-101-G3(27-30U)
A18: =IF(C18="","",SUBTOTAL(103,$C$2:C18)) -> 17 | B18: 5 | C18: 11202 | D18: 安全保密 | E18: 防火墙 | F18: 华为 USG6660 | G18: 210235G7G510EA000011 | H18: 140601-2014-000013 | I18: 12 | J18: =VLOOKUP(G18,[1]硬件清单!$F:$F,1,0) -> 210235G7G510EA000011 | K18: =VLOOKUP(G18,[1]硬件清单!$F:$F,1,0) -> 210235G7G510EA000011 | M18: TK-F01-101-G3(35-37U)
A19: =IF(C19="","",SUBTOTAL(103,$C$2:C19)) -> 18 | B19: 6 | C19: 11101 | D19: 网络设备 | E19: 交换机 | F19: 华三 S12510-X | G19: 210235AOXXX149000022 | H19: 140502-2014-001092 | I19: 12 | J19: =VLOOKUP(G19,[1]硬件清单!$F:$F,1,0) -> 210235AOXXX149000022 | K19: =VLOOKUP(G19,[1]硬件清单!$F:$F,1,0) -> 210235AOXXX149000022 | L19: 原厂 | M19: TK-F01-101-G2(3-23U)
A20: =IF(C20="","",SUBTOTAL(103,$C$2:C20)) -> 19 | B20: 7 | C20: 10150 | D20: 网络设备 | E20: 应用负载均衡器 | F20: F5 2400 | G20: chs408155s (bid009916s bid009926s) | H20: 140504-2014-000397 | I20: 12 | J20: =VLOOKUP(G20,[1]硬件清单!$F:$F,1,0) -> chs408155s (bid009916s bid009926s) | K20: =VLOOKUP(G20,[1]硬件清单!$F:$F,1,0) -> chs408155s (bid009916s bid009926s) | L20: 原厂 | M20: TK-F01-101-G4(10-13U)
A21: =IF(C21="","",SUBTOTAL(103,$C$2:C21)) -> 20 | B21: 8 | C21: 10151 | D21: 网络设备 | E21: 应用负载均衡器 | F21: Radware alteon5412 | G21: 31405652 | H21: 140504-2014-000398 | I21: 12 | J21: =VLOOKUP(G21,[1]硬件清单!$F:$F,1,0) -> 31405652 | K21: =VLOOKUP(G21,[1]硬件清单!$F:$F,1,0) -> 31405652 | M21: TK-F01-101-G4(16-17U)
A22: =IF(C22="","",SUBTOTAL(103,$C$2:C22)) -> 21 | B22: 9 | C22: 10152 | D22: 网络设备 | E22: 应用负载均衡器 | F22: Radware alteon5412 | G22: 31405713 | H22: 140504-2014-000399 | I22: 12 | J22: =VLOOKUP(G22,[1]硬件清单!$F:$F,1,0) -> 31405713 | K22: =VLOOKUP(G22,[1]硬件清单!$F:$F,1,0) -> 31405713 | M22: TK-F01-101-G4(19-20U)
A23: =IF(C23="","",SUBTOTAL(103,$C$2:C23)) -> 22 | B23: 10 | C23: 11214 | D23: 安全保密 | E23: 加密设备 | F23: F5 VIPROPN 2400 | G23: chs408180s | H23: 140606-2014-000006 | I23: 12 | J23: =VLOOKUP(G23,[1]硬件清单!$F:$F,1,0) -> chs408180s | K23: =VLOOKUP(G23,[1]硬件清单!$F:$F,1,0) -> chs408180s | L23: 原厂 | M23: TK-F01-101-G4(27-30U)
A24: =IF(C24="","",SUBTOTAL(103,$C$2:C24)) -> 23 | B24: 11 | C24: 11203 | D24: 安全保密 | E24: 防火墙 | F24: 华为 USG6660 | G24: 210235G7G510EA000008 | H24: 140601-2014-000014 | I24: 12 | J24: =VLOOKUP(G24,[1]硬件清单!$F:$F,1,0) -> 210235G7G510EA000008 | K24: =VLOOKUP(G24,[1]硬件清单!$F:$F,1,0) -> 210235G7G510EA000008 | M24: TK-F01-101-G4(34-36U)
A25: =IF(C25="","",SUBTOTAL(103,$C$2:C25)) -> 24 | B25: 12 | C25: 10149 | D25: 网络设备 | E25: 应用负载均衡器 | F25: F5 2400 | G25: chs408153s (bid009925s bid009913s) | H25: 140504-2014-000396 | I25: 12 | J25: =VLOOKUP(G25,[1]硬件清单!$F:$F,1,0) -> chs408153s (bid009925s bid009913s) | K25: =VLOOKUP(G25,[1]硬件清单!$F:$F,1,0) -> chs408153s (bid009925s bid009913s) | M25: TK-F01-101-G4(4-7U)
A26: =IF(C26="","",SUBTOTAL(103,$C$2:C26)) -> 25 | B26: 14 | C26: 11204 | D26: 安全保密 | E26: 防火墙 | F26: 华为 USG9520 | G26: 210235A0HAH14A000296 | H26: 140601-2014-000015 | I26: 12 | J26: =VLOOKUP(G26,[1]硬件清单!$F:$F,1,0) -> 210235A0HAH14A000296 | K26: =VLOOKUP(G26,[1]硬件清单!$F:$F,1,0) -> 210235A0HAH14A000296 | M26: TK-F01-101-G5(20-24U)
A27: =IF(C27="","",SUBTOTAL(103,$C$2:C27)) -> 26 | B27: 15 | C27: 11215 | D27: 安全保密 | E27: 加密设备 | F27: F5 VIPROPN 2400 | G27: chs408149s | H27: 140606-2014-000007 | I27: 12 | J27: =VLOOKUP(G27,[1]硬件清单!$F:$F,1,0) -> chs408149s | K27: =VLOOKUP(G27,[1]硬件清单!$F:$F,1,0) -> chs408149s | L27: 原厂 | M27: TK-F01-101-G5(27-30U)
A28: =IF(C28="","",SUBTOTAL(103,$C$2:C28)) -> 27 | B28: 16 | C28: 11084 | D28: 网络设备 | E28: 路由器 | F28: 思科 ASR1004-CB | G28: FXS1751Q1KZ | H28: 140501-2014-000553 | I28: 12 | J28: =VLOOKUP(G28,[1]硬件清单!$F:$F,1,0) -> FXS1751Q1KZ | K28: =VLOOKUP(G28,[1]硬件清单!$F:$F,1,0) -> FXS1751Q1KZ | L28: 原厂 | M28: TK-F01-101-G5(3-6U)
A29: =IF(C29="","",SUBTOTAL(103,$C$2:C29)) -> 28 | B29: 19 | C29: 11205 | D29: 安全保密 | E29: 防火墙 | F29: 华为 USG9520 | G29: 210235A0HAH14A000246 | H29: 140601-2014-000016 | I29: 12 | J29: =VLOOKUP(G29,[1]硬件清单!$F:$F,1,0) -> 210235A0HAH14A000246 | K29: =VLOOKUP(G29,[1]硬件清单!$F:$F,1,0) -> 210235A0HAH14A000246 | M29: TK-F01-101-G6(20-24U)
A30: =IF(C30="","",SUBTOTAL(103,$C$2:C30)) -> 29 | B30: 20 | C30: 11216 | D30: 安全保密 | E30: 加密设备 | F30: F5 VIPROPN 2400 | G30: chs408151s | H30: 140606-2014-000008 | I30: 12 | J30: =VLOOKUP(G30,[1]硬件清单!$F:$F,1,0) -> chs408151s | K30: =VLOOKUP(G30,[1]硬件清单!$F:$F,1,0) -> chs408151s | L30: 原厂 | M30: TK-F01-101-G6(27-30U)
A31: =IF(C31="","",SUBTOTAL(103,$C$2:C31)) -> 30 | B31: 21 | C31: 11085 | D31: 网络设备 | E31: 路由器 | F31: 思科 ASR1004-CB | G31: FXS1745Q0TX | H31: 140501-2014-000554 | I31: 12 | J31: =VLOOKUP(G31,[1]硬件清单!$F:$F,1,0) -> FXS1745Q0TX | K31: =VLOOKUP(G31,[1]硬件清单!$F:$F,1,0) -> FXS1745Q0TX | M31: TK-F01-101-G6(3-6U)
A32: =IF(C32="","",SUBTOTAL(103,$C$2:C32)) -> 31 | B32: 23 | C32: 11413 | D32: 机房设备 | E32: 空调系统 | F32: 艾默生PEX系列－P2070 | G32: 2101301843213b040001 | H32: 140702-2014-000018 | I32: 12 | J32: =VLOOKUP(G32,[1]硬件清单!$F:$F,1,0) -> 2101301843213b040001 | K32: =VLOOKUP(G32,[1]硬件清单!$F:$F,1,0) -> 2101301843213b040001 | M32: TK-F01-101东侧空调
A33: =IF(C33="","",SUBTOTAL(103,$C$2:C33)) -> 32 | B33: 24 | C33: 11414 | D33: 机房设备 | E33: 空调系统 | F33: 艾默生PEX系列－P2070 | G33: 21013018432133030008 | H33: 140702-2014-000019 | I33: 12 | J33: =VLOOKUP(G33,[1]硬件清单!$F:$F,1,0) -> 21013018432133030008 | K33: =VLOOKUP(G33,[1]硬件清单!$F:$F,1,0) -> 21013018432133030008 | M33: TK-F01-101西侧空调
A34: =IF(C34="","",SUBTOTAL(103,$C$2:C34)) -> 33 | B34: 25 | C34: 11097 | D34: 网络设备 | E34: 路由器 | F34: 华为 AR2240 | G34: 2102113373POE9000338 | H34: 140501-2014-000566 | I34: 12 | J34: =VLOOKUP(G34,[1]硬件清单!$F:$F,1,0) -> 2102113373POE9000338 | K34: =VLOOKUP(G34,[1]硬件清单!$F:$F,1,0) -> 2102113373POE9000338 | M34: TK-F01-104-H1(14-15U)
A35: =IF(C35="","",SUBTOTAL(103,$C$2:C35)) -> 34 | B35: 26 | C35: 11096 | D35: 网络设备 | E35: 路由器 | F35: 华为 AR2240 | G35: 21021133736TEA900017 | H35: 140501-2014-000565 | I35: 12 | J35: =VLOOKUP(G35,[1]硬件清单!$F:$F,1,0) -> 21021133736TEA900017 | K35: =VLOOKUP(G35,[1]硬件清单!$F:$F,1,0) -> 21021133736TEA900017 | M35: TK-F01-104-H1(17-18U)
A36: =IF(C36="","",SUBTOTAL(103,$C$2:C36)) -> 35 | B36: 27 | C36: 11213 | D36: 安全保密 | E36: 防火墙 | F36: 华为 USG6530 | G36: 210235951510EA000034 | H36: 140601-2014-000024 | I36: 12 | J36: =VLOOKUP(G36,[1]硬件清单!$F:$F,1,0) -> 210235951510EA000034 | K36: =VLOOKUP(G36,[1]硬件清单!$F:$F,1,0) -> 210235951510EA000034 | M36: TK-F01-104-H2(14-14U)
A37: =IF(C37="","",SUBTOTAL(103,$C$2:C37)) -> 36 | B37: 28 | C37: 11212 | D37: 安全保密 | E37: 防火墙 | F37: 华为 USG6530 | G37: 210235951510EA000050 | H37: 140601-2014-000023 | I37: 12 | J37: =VLOOKUP(G37,[1]硬件清单!$F:$F,1,0) -> 210235951510EA000050 | K37: =VLOOKUP(G37,[1]硬件清单!$F:$F,1,0) -> 210235951510EA000050 | M37: TK-F01-104-H2(16-16U)
A38: =IF(C38="","",SUBTOTAL(103,$C$2:C38)) -> 37 | B38: 29 | C38: 11093 | D38: 网络设备 | E38: 路由器 | F38: 华为 AR2240 | G38: 21021133736TEA900076 | H38: 140501-2014-000562 | I38: 12 | J38: =VLOOKUP(G38,[1]硬件清单!$F:$F,1,0) -> 21021133736TEA900076 | K38: =VLOOKUP(G38,[1]硬件清单!$F:$F,1,0) -> 21021133736TEA900076 | M38: TK-F01-104-H2(19-20U)
A39: =IF(C39="","",SUBTOTAL(103,$C$2:C39)) -> 38 | B39: 30 | C39: 11092 | D39: 网络设备 | E39: 路由器 | F39: 华为 AR2240 | G39: 21021133736TEA900021 | H39: 140501-2014-000561 | I39: 12 | J39: =VLOOKUP(G39,[1]硬件清单!$F:$F,1,0) -> 21021133736TEA900021 | K39: =VLOOKUP(G39,[1]硬件清单!$F:$F,1,0) -> 21021133736TEA900021 | M39: TK-F01-104-H2(22-23U)
A40: =IF(C40="","",SUBTOTAL(103,$C$2:C40)) -> 39 | B40: 31 | C40: 11095 | D40: 网络设备 | E40: 路由器 | F40: 华为 AR2240 | G40: 21021133736TEA900022 | H40: 140501-2014-000564 | I40: 12 | J40: =VLOOKUP(G40,[1]硬件清单!$F:$F,1,0) -> 21021133736TEA900022 | K40: =VLOOKUP(G40,[1]硬件清单!$F:$F,1,0) -> 21021133736TEA900022 | M40: TK-F01-104-H2(26-27U)
...

Sheet 软件清单
A1: 序号 | B1: 采购事项 | C1: 产品名称 | D1: S/N | E1: 服务期限（月） | F1: 需求说明 | G1: 备注
A2: 1 | B2: 软件 | C2: EMCNetworkerV8.2 | E2: 12 | F2: 中标人提供
A3: 2 | B3: 软件 | C3: Oracle 11g企业版 | E3: 12 | F3: 中标人提供
A4: 3 | B4: 软件 | C4: Weblogic企业版 | E4: 12 | F4: 中标人提供
A5: 4 | B5: 软件 | C5: 分布式内存数据库软件PivotalGemFire企业版License | E5: 12 | F5: 中标人提供
A6: 5 | B6: 软件 | C6: GoldenGate12CProcessor | E6: 12 | F6: 中标人提供
A7: 6 | B7: 软件 | C7: Oracle linux | E7: 12 | F7: 原厂20人天
A8: 7 | B8: 软件 | C8: WCM系统 | E8: 12 | F8: 中标人提供
A9: 8 | B9: 软件 | C9: 邮件归档系统maildatav3.2.3(2套) | E9: 12 | F9: 中标人提供
A10: 9 | B10: 软件 | C10: 邮件网关系统maildatav2.8.2(2套) | E10: 12 | F10: 中标人提供
A11: 10 | B11: 软件 | C11: 邮件网关系统maildatav2.8.3(2套) | E11: 12 | F11: 中标人提供
A12: 11 | B12: 软件 | C12: 邮件系统V7.0(2套) | E12: 12 | F12: 中标人提供
A13: 12 | B13: 软件 | C13: TRSWCMv7.01套 | E13: 12 | F13: 中标人提供
... A31: 30 | B31: 软件 | C31: 铁路公安系统V1.0 | E31: 12 | F31: 中标人提供
A32: 31 | B32: 软件 | C32: 360安全浏览软件XC-IIBR1300-C-SW | D32: 3套 | E32: 1 | F32: 原厂标服
A33: 32 | B33: 软件 | C33: H3C CAS软件 V7.0 | D33: 1套 | E33: 12 | F33: 原厂标服
A34: 33 | B34: 软件 | C34: Oracle Linux | D34: 177套 | E34: 12 | F34: 原厂标服
A35: 34 | B35: 软件 | C35: VMware vSphere 7.0企业增强版 | D35: 1套 | E35: 12 | F35: 中标人提供
A36: 35 | B36: 软件 | C36: Windows Server 2022 | D36: 5套 | E36: 12 | F36: 中标人提供
A37: 36 | B37: 软件 | C37: 安超虚拟化平台软件 V1.5 标准版 | D37: 1套 | E37: 12 | F37: 中标人提供
A38: 37 | B38: 软件 | C38: 北京经纬信息移动安全管理平台V1.0（管理） | D38: 1套 | E38: 1 | F38: 原厂标服
A39: 38 | B39: 软件 | C39: 北京经纬信息移动安全管理平台V1.0（接入） | D39: 1套 | E39: 1 | F39: 原厂标服
A40: 39 | B40: 软件 | C40: 北京酷德啄木鸟CodeCheck源代码缺陷分析系统V4.0、软件成分分析系统 | D40: 1套 | E40: 1 | F40: 原厂标服
A41: 40 | B41: 软件 | C41: 北京数字认证SYT1812-G密钥管理系统 | D41: 2套 | E41: 1 | F41: 原厂标服
A42: 41 | B42: 软件 | C42: 北京数字认证SZT1802-G数字证书认证系统 | D42: 2套 | E42: 1 | F42: 原厂标服
A43: 42 | B43: 软件 | C43: 北京数字认证密码服务管理平台CSCP-AV1.0 | D43: 2套 | E43: 1 | F43: 原厂标服
... A47: 46 | B47: 软件 | C47: 统信服务器操作系统 V20 | D47: 30套 | E47: 12 | F47: 原厂标服+20人天现场服务
A48: 47 | B48: 软件 | D48: 257套 | E48: 1
A49: 48 | B49: 软件 | C49: 兴唐通信SDT1930 | D49: 1套 | E49: 1 | F49: 原厂标服
A50: 49 | B50: 软件 | C50: 兴唐通信SDT-KMS | D50: 1套 | E50: 1 | F50: 原厂标服
A51: 50 | B51: 软件 | C51: 兴唐通信密码服务网关系统SDT222201-G | D51: 1套 | E51: 1 | F51: 原厂标服
A52: 51 | B52: 软件 | C52: 银河麒麟高级服务器操作系统V10 | D52: 320套 | E52: 1 | F52: 原厂标服+20人天现场服务
D53: 30套 | E53: 12
A54: 52 | B54: 软件 | C54: 永达EME4280 | D54: 1套 | E54: 1 | F54: 原厂标服
A55: 53 | B55: 软件 | C55: 云宏CNware WinSphere服务器虚拟化软件V8.2 | D55: 1套 | E55: 12 | F55: 中标人提供

Sheet 硬件人天清单
A1: 序号 | B1: 设备品牌 | C1: 原厂人天 | D1: 中标人人天 | E1: 备注
A2: 1 | B2: 华为存储 | C2: 2 | D2: 10
A3: 2 | B3: 宏杉存储 | C3: 2 | D3: 10
A4: 3 | B4: 思科SAN交换机 | C4: 3 | D4: 10
A5: 4 | B5: 浪潮存储 | C5: 5 | D5: 15
A6: 5 | B6: EMC存储 | C6: 6 | D6: 0
A7: 6 | B7: 信安世纪负载均衡 | C7: 15 | D7: 35
A8: 7 | B8: 浪潮小型机 | C8: 15 | D8: 0
A9: 8 | B9: 思科网络（增强） | C9: 5 | D9: 15
A10: 9 | B10: 网络工程师驻厂服务 | D10: 配置2人年的网络维护服务。 | E10: 需求说明：配置2人年的网络维护服务，进行5x8小时网络保障。采购网络工区保障服务，配置2人的保障人员，进行5x8小时网络保障，协助开展公共基础网络设备及链路的监测分析、远程巡检、常规养护、旁站盯控等基础性工作。
A11: 10 | B11: 永达工程师驻场服务 | D11: 配置2人年的永达设备维护服务。 | E11: 需求说明：永达隔离相关设备用于客票网与其他网络的安全隔离，设备数量达到500多台，运维资料不全、设备老旧，需配置2人年的维护服务，进行永达设备维护保障，进行5x8小时的驻场保障服务和7x24小时的二线保障服务，协助开展12306中永达设备的设备巡检、故障处置、问题分析、软件升级等工作。
